# promise相关

###### 1、基本概念

promise是用来解决异步编程的方法

（1）、语法上：promise是一个构造函数

（2）、功能上：promise封装一个异步操作并返回其结果

```js
let promise = new Promise(function(resolve, reject) {
  // 当 promise 被构造完成时，自动执行此函数

  // 1 秒后发出工作已经被完成的信号，并带有结果 "done"
  setTimeout(() => resolve("done"), 1000);
});
```

```js
const myFirstPromise = new Promise((resolve, reject) => {
  // ?做一些异步操作，最终会调用下面两者之一:
  //
  //   resolve(someValue); // fulfilled
  // ?或
  //   reject("failure reason"); // rejected
});
```

```js
let myFirstPromise = new Promise(function(resolve, reject){
    //当异步代码执行成功时，我们才会调用resolve(...), 当异步代码失败时就会调用reject(...)
    //在本例中，我们使用setTimeout(...)来模拟异步代码，实际编码时可能是XHR请求或是HTML5的一些API方法.
    setTimeout(function(){
        resolve("成功!"); //代码正常执行！
    }, 250);
});

myFirstPromise.then(
    function(successMessage){
        //successMessage的值是上面调用resolve(...)方法传入的值.
        //successMessage参数不一定非要是字符串类型，这里只是举个例子
        console.log("Yay! " + successMessage);
	}
);
```

```js
let promise = new Promise(function(resolve, reject) {
  setTimeout(() => resolve("done!"), 1000);
});

// resolve 运行 .then 中的第一个函数
promise.then(
  result => alert(result), // 1 秒后显示 "done!"
  error => alert(error) // 不运行
);
```

```js
let promise = new Promise(function(resolve, reject) {
  setTimeout(() => reject(new Error("Whoops!")), 1000);
});

// reject 运行 .then 中的第二个函数
promise.then(
  result => alert(result), // 不运行
  error => alert(error) // 1 秒后显示 "Error: Whoops!"
);
```

```js
let promise = new Promise((resolve, reject) => {
  setTimeout(() => reject(new Error("Whoops!")), 1000);
});

// .catch(f) 与 promise.then(null, f) 一样
promise.catch(alert); // 1 秒后显示 "Error: Whoops!"
```

```js
new Promise((resolve, reject) => {
  /* 做一些需要时间的事儿，然后调用 resolve/reject */
})
  // 在 promise 为 settled 时运行，无论成功与否
  .finally(() => stop loading indicator)
  // 所以，加载指示器（loading indicator）始终会在我们处理结果/错误之前停止
  .then(result => show result, err => show error)
```

```js
new Promise((resolve, reject) => {
  throw new Error("error");
})
  .finally(() => alert("Promise ready"))
  .catch(err => alert(err));  // <-- .catch 对 error 对象进行处理	
```

