# 错误与错误处理

## 错误

在具体的项目开发中，我们可能是因为我们的编写出错，或是与预期不同的用户输入，或是错误的服务端响应以及其他数千种原因。在这个时候程序就会报错。会抛出一个Error对象

因此我们想要调试我们的错误，就需要能看懂Error对象

```JS
// 下列代码会出现错误，由于重复定义相通变量名
let a = 1;
const a = 1;

// SyntaxError: Identifier 'a' has already been declared
//     at Object.compileFunction (node:vm:352:18)
//     at wrapSafe (node:internal/modules/cjs/loader:1031:15)
//     at Module._compile (node:internal/modules/cjs/loader:1065:27)
//     at Object.Module._extensions..js (node:internal/modules/cjs/loader:1153:10)
//     at Module.load (node:internal/modules/cjs/loader:981:32)
//     at Function.Module._load (node:internal/modules/cjs/loader:822:12)
//     at Function.executeUserEntryPoint [as runMain] (node:internal/modules/run_main:79:12)
//     at node:internal/main/run_main_module:17:47
// 会直接抛出一个错误对象，我们来观察下这个对象的结构。
// `SyntaxError` 是Error对象的名字。在这个例子中代表他是一个语法错误。
// 'Identifier 'a' has already been declared' 是Error对象的信息。在这个例子代表标识符“a”已经声明
// 下面的 以at开头的语句代表Error对象的调用栈，代表有关导致 error 的调用的错误信息。

```

所以我们可以看到Error对象包括三个属性 name（名字）, message（信息）, stack（具体调用栈）;

除了程序错误，我们还可以自己抛出错误，来自定义程序问题

```js
let a = 0;
a += 1;
// 我们使用 new Error的形式自定义自己的错误，

throw new Error('发生错误');
// 其中error的结构是这个样子的
/*
erorr = {
  name: 'Error', // 字符串
  message: '发生错误', // 字符串
  stack: `
    at Object.<anonymous> (C:\Users\a4553\works\demo\js-demo\src\index.js:5:7)
    at Module._compile (node:internal/modules/cjs/loader:1101:14)
    at Object.Module._extensions..js (node:internal/modules/cjs/loader:1153:10)
    at Module.load (node:internal/modules/cjs/loader:981:32)
    at Function.Module._load (node:internal/modules/cjs/loader:822:12)
    at Function.executeUserEntryPoint [as runMain] (node:internal/modules/run_main:79:12)
    at node:internal/main/run_main_module:17:47
  ` // 字符串
}
*/
```

## 错误处理

就算我们再小心，也有可能因为后端传递过来的数据导致错误。通常，如果发生错误，程序就会“崩溃”（立即停止），并在控制台将错误打印出来。我们为了能让程序可以执行更合理的操作，而不是直接崩溃。

我们可以使用`try` - `catch`的形式捕捉程序错误

```js
try {
  console.log('Start of try runs'); // (1) 能够执行

  lalala; // Error，变量未定义！

  console.log('End of try (never reached)'); // (2) 由于上个语句发生错误，直接停止执行try语句块，所以这句语句无法执行
} catch (err) {
  console.log(`Error has occurred!`); // (3) <-- 能够执行
}

// Start of try runs
// Error has occurred!

```

****

```js
try {
  console.log(a); //使用不存在的变量， <-- 当出现一个 error 时...
  console.log('hello error'); // 不工作
} catch (e) {
  // ...执行会跳转到这里并继续执行
  console.log('这里捕捉到的错误，会赋值给e。即那个e就是捕捉到的错误对象');
  console.log(e.name); // ReferenceError
  console.log(e.message); // a is not defined
}

```

我们知道try语句块在执行错误时，会直接停止执行。转而去执行catch语句块。但有时，我们希望无论是否出现错误都要想完成某个任务。我们可以有以下这样的做法

```js
try {
  // 尝试执行，
  console.log('无论是否发生错误都执行的任务'); // 若成功，则会执行这一步
} catch (e) {
  // ...执行会跳转到这里并继续执行
  console.log('无论是否发生错误都执行的任务'); // 若发生错误，则会执行这一步
}
```

但实际上js提供了一个更方便的方 – **`finally` 语句块**。 无论是否出现错误都会执行的语句块。

```js
try {
  // 尝试执行，
  
} catch (e) {
  // ...执行会跳转到这里并继续执行
  
} finally {
  console.log('无论是否发生错误都执行的任务'); 
}
```

## 练习

```js
// 1. 如何使用throw抛出错误

// 2. 如何使用 try,catch语句捕捉错误，避免程序崩溃

// 3. 体会finally语句块的语法和作用
```



